{
 "metadata": {
  "language_info": {
   "codemirror_mode": {
    "name": "ipython",
    "version": 3
   },
   "file_extension": ".py",
   "mimetype": "text/x-python",
   "name": "python",
   "nbconvert_exporter": "python",
   "pygments_lexer": "ipython3",
   "version": "3.8.5-final"
  },
  "orig_nbformat": 2,
  "kernelspec": {
   "name": "python3",
   "display_name": "Python 3.8.5 64-bit ('pytorch_en': conda)",
   "metadata": {
    "interpreter": {
     "hash": "ab8ad6ca2f0cb10c3029d73141061dd20c965aa5b182da4caedb529d07f8324a"
    }
   }
  }
 },
 "nbformat": 4,
 "nbformat_minor": 2,
 "cells": [
  {
   "cell_type": "code",
   "execution_count": 6,
   "metadata": {},
   "outputs": [
    {
     "output_type": "error",
     "ename": "ModuleNotFoundError",
     "evalue": "No module named 'torchvision'",
     "traceback": [
      "\u001b[0;31m---------------------------------------------------------------------------\u001b[0m",
      "\u001b[0;31mModuleNotFoundError\u001b[0m                       Traceback (most recent call last)",
      "\u001b[0;32m<ipython-input-6-ccac5324059b>\u001b[0m in \u001b[0;36m<module>\u001b[0;34m\u001b[0m\n\u001b[1;32m     11\u001b[0m \u001b[0;32mimport\u001b[0m \u001b[0mtorch\u001b[0m\u001b[0;34m.\u001b[0m\u001b[0moptim\u001b[0m \u001b[0;32mas\u001b[0m \u001b[0moptim\u001b[0m\u001b[0;34m\u001b[0m\u001b[0;34m\u001b[0m\u001b[0m\n\u001b[1;32m     12\u001b[0m \u001b[0;32mimport\u001b[0m \u001b[0mtorch\u001b[0m\u001b[0;34m.\u001b[0m\u001b[0mutils\u001b[0m\u001b[0;34m.\u001b[0m\u001b[0mdata\u001b[0m\u001b[0;34m\u001b[0m\u001b[0;34m\u001b[0m\u001b[0m\n\u001b[0;32m---> 13\u001b[0;31m \u001b[0;32mimport\u001b[0m \u001b[0mtorchvision\u001b[0m\u001b[0;34m.\u001b[0m\u001b[0mdatasets\u001b[0m \u001b[0;32mas\u001b[0m \u001b[0mdset\u001b[0m\u001b[0;34m\u001b[0m\u001b[0;34m\u001b[0m\u001b[0m\n\u001b[0m\u001b[1;32m     14\u001b[0m \u001b[0;32mimport\u001b[0m \u001b[0mtorchvision\u001b[0m\u001b[0;34m.\u001b[0m\u001b[0mtransforms\u001b[0m \u001b[0;32mas\u001b[0m \u001b[0mtransforms\u001b[0m\u001b[0;34m\u001b[0m\u001b[0;34m\u001b[0m\u001b[0m\n\u001b[1;32m     15\u001b[0m \u001b[0;32mimport\u001b[0m \u001b[0mtorchvision\u001b[0m\u001b[0;34m.\u001b[0m\u001b[0mutils\u001b[0m \u001b[0;32mas\u001b[0m \u001b[0mvutils\u001b[0m\u001b[0;34m\u001b[0m\u001b[0;34m\u001b[0m\u001b[0m\n",
      "\u001b[0;31mModuleNotFoundError\u001b[0m: No module named 'torchvision'"
     ]
    }
   ],
   "source": [
    "#Importing Librarires\n",
    "\n",
    "import os\n",
    "import sys\n",
    "\n",
    "import numpy as np\n",
    "import torch\n",
    "import torch.nn as nn\n",
    "import torch.nn.parallel\n",
    "import torch.backends.cudnn as cudnn\n",
    "import torch.optim as optim\n",
    "import torch.utils.data\n",
    "import torchvision.datasets as dset\n",
    "import torchvision.transforms as transforms\n",
    "import torchvision.utils as vutils\n",
    "\n",
    "import utils\n",
    "\n",
    "############################"
   ]
  },
  {
   "cell_type": "code",
   "execution_count": 11,
   "metadata": {},
   "outputs": [
    {
     "output_type": "stream",
     "name": "stdout",
     "text": [
      "Collecting torchvision\n",
      "  Using cached torchvision-0.8.2-cp38-cp38-manylinux1_x86_64.whl (12.8 MB)\n",
      "Requirement already satisfied: numpy in ./anaconda3/envs/pytorch_source/lib/python3.8/site-packages (from torchvision) (1.19.2)\n",
      "Collecting torch==1.7.1\n",
      "  Downloading torch-1.7.1-cp38-cp38-manylinux1_x86_64.whl (776.8 MB)\n",
      "\u001b[K     |â–‹                               | 14.6 MB 507 kB/s eta 0:25:04\u001b[31mERROR: Exception:\n",
      "Traceback (most recent call last):\n",
      "  File \"/home/t/anaconda3/envs/pytorch_source/lib/python3.8/site-packages/pip/_vendor/urllib3/response.py\", line 438, in _error_catcher\n",
      "    yield\n",
      "  File \"/home/t/anaconda3/envs/pytorch_source/lib/python3.8/site-packages/pip/_vendor/urllib3/response.py\", line 519, in read\n",
      "    data = self._fp.read(amt) if not fp_closed else b\"\"\n",
      "  File \"/home/t/anaconda3/envs/pytorch_source/lib/python3.8/site-packages/pip/_vendor/cachecontrol/filewrapper.py\", line 62, in read\n",
      "    data = self.__fp.read(amt)\n",
      "  File \"/home/t/anaconda3/envs/pytorch_source/lib/python3.8/http/client.py\", line 458, in read\n",
      "    n = self.readinto(b)\n",
      "  File \"/home/t/anaconda3/envs/pytorch_source/lib/python3.8/http/client.py\", line 502, in readinto\n",
      "    n = self.fp.readinto(b)\n",
      "  File \"/home/t/anaconda3/envs/pytorch_source/lib/python3.8/socket.py\", line 669, in readinto\n",
      "    return self._sock.recv_into(b)\n",
      "  File \"/home/t/anaconda3/envs/pytorch_source/lib/python3.8/ssl.py\", line 1241, in recv_into\n",
      "    return self.read(nbytes, buffer)\n",
      "  File \"/home/t/anaconda3/envs/pytorch_source/lib/python3.8/ssl.py\", line 1099, in read\n",
      "    return self._sslobj.read(len, buffer)\n",
      "socket.timeout: The read operation timed out\n",
      "\n",
      "During handling of the above exception, another exception occurred:\n",
      "\n",
      "Traceback (most recent call last):\n",
      "  File \"/home/t/anaconda3/envs/pytorch_source/lib/python3.8/site-packages/pip/_internal/cli/base_command.py\", line 224, in _main\n",
      "    status = self.run(options, args)\n",
      "  File \"/home/t/anaconda3/envs/pytorch_source/lib/python3.8/site-packages/pip/_internal/cli/req_command.py\", line 180, in wrapper\n",
      "    return func(self, options, args)\n",
      "  File \"/home/t/anaconda3/envs/pytorch_source/lib/python3.8/site-packages/pip/_internal/commands/install.py\", line 320, in run\n",
      "    requirement_set = resolver.resolve(\n",
      "  File \"/home/t/anaconda3/envs/pytorch_source/lib/python3.8/site-packages/pip/_internal/resolution/resolvelib/resolver.py\", line 121, in resolve\n",
      "    self._result = resolver.resolve(\n",
      "  File \"/home/t/anaconda3/envs/pytorch_source/lib/python3.8/site-packages/pip/_vendor/resolvelib/resolvers.py\", line 445, in resolve\n",
      "    state = resolution.resolve(requirements, max_rounds=max_rounds)\n",
      "  File \"/home/t/anaconda3/envs/pytorch_source/lib/python3.8/site-packages/pip/_vendor/resolvelib/resolvers.py\", line 339, in resolve\n",
      "    failure_causes = self._attempt_to_pin_criterion(name, criterion)\n",
      "  File \"/home/t/anaconda3/envs/pytorch_source/lib/python3.8/site-packages/pip/_vendor/resolvelib/resolvers.py\", line 207, in _attempt_to_pin_criterion\n",
      "    criteria = self._get_criteria_to_update(candidate)\n",
      "  File \"/home/t/anaconda3/envs/pytorch_source/lib/python3.8/site-packages/pip/_vendor/resolvelib/resolvers.py\", line 198, in _get_criteria_to_update\n",
      "    for r in self._p.get_dependencies(candidate):\n",
      "  File \"/home/t/anaconda3/envs/pytorch_source/lib/python3.8/site-packages/pip/_internal/resolution/resolvelib/provider.py\", line 170, in get_dependencies\n",
      "    return [\n",
      "  File \"/home/t/anaconda3/envs/pytorch_source/lib/python3.8/site-packages/pip/_internal/resolution/resolvelib/provider.py\", line 170, in <listcomp>\n",
      "    return [\n",
      "  File \"/home/t/anaconda3/envs/pytorch_source/lib/python3.8/site-packages/pip/_internal/resolution/resolvelib/candidates.py\", line 257, in iter_dependencies\n",
      "    requires = self.dist.requires() if with_requires else ()\n",
      "  File \"/home/t/anaconda3/envs/pytorch_source/lib/python3.8/site-packages/pip/_internal/resolution/resolvelib/candidates.py\", line 239, in dist\n",
      "    self._prepare()\n",
      "  File \"/home/t/anaconda3/envs/pytorch_source/lib/python3.8/site-packages/pip/_internal/resolution/resolvelib/candidates.py\", line 226, in _prepare\n",
      "    dist = self._prepare_distribution()\n",
      "  File \"/home/t/anaconda3/envs/pytorch_source/lib/python3.8/site-packages/pip/_internal/resolution/resolvelib/candidates.py\", line 318, in _prepare_distribution\n",
      "    return self._factory.preparer.prepare_linked_requirement(\n",
      "  File \"/home/t/anaconda3/envs/pytorch_source/lib/python3.8/site-packages/pip/_internal/operations/prepare.py\", line 480, in prepare_linked_requirement\n",
      "    return self._prepare_linked_requirement(req, parallel_builds)\n",
      "  File \"/home/t/anaconda3/envs/pytorch_source/lib/python3.8/site-packages/pip/_internal/operations/prepare.py\", line 503, in _prepare_linked_requirement\n",
      "    local_file = unpack_url(\n",
      "  File \"/home/t/anaconda3/envs/pytorch_source/lib/python3.8/site-packages/pip/_internal/operations/prepare.py\", line 253, in unpack_url\n",
      "    file = get_http_url(\n",
      "  File \"/home/t/anaconda3/envs/pytorch_source/lib/python3.8/site-packages/pip/_internal/operations/prepare.py\", line 130, in get_http_url\n",
      "    from_path, content_type = download(link, temp_dir.path)\n",
      "  File \"/home/t/anaconda3/envs/pytorch_source/lib/python3.8/site-packages/pip/_internal/network/download.py\", line 163, in __call__\n",
      "    for chunk in chunks:\n",
      "  File \"/home/t/anaconda3/envs/pytorch_source/lib/python3.8/site-packages/pip/_internal/cli/progress_bars.py\", line 168, in iter\n",
      "    for x in it:\n",
      "  File \"/home/t/anaconda3/envs/pytorch_source/lib/python3.8/site-packages/pip/_internal/network/utils.py\", line 64, in response_chunks\n",
      "    for chunk in response.raw.stream(\n",
      "  File \"/home/t/anaconda3/envs/pytorch_source/lib/python3.8/site-packages/pip/_vendor/urllib3/response.py\", line 576, in stream\n",
      "    data = self.read(amt=amt, decode_content=decode_content)\n",
      "  File \"/home/t/anaconda3/envs/pytorch_source/lib/python3.8/site-packages/pip/_vendor/urllib3/response.py\", line 541, in read\n",
      "    raise IncompleteRead(self._fp_bytes_read, self.length_remaining)\n",
      "  File \"/home/t/anaconda3/envs/pytorch_source/lib/python3.8/contextlib.py\", line 131, in __exit__\n",
      "    self.gen.throw(type, value, traceback)\n",
      "  File \"/home/t/anaconda3/envs/pytorch_source/lib/python3.8/site-packages/pip/_vendor/urllib3/response.py\", line 443, in _error_catcher\n",
      "    raise ReadTimeoutError(self._pool, None, \"Read timed out.\")\n",
      "pip._vendor.urllib3.exceptions.ReadTimeoutError: HTTPSConnectionPool(host='files.pythonhosted.org', port=443): Read timed out.\u001b[0m\n",
      "Note: you may need to restart the kernel to use updated packages.\n"
     ]
    }
   ],
   "source": [
    "pip install torchvision"
   ]
  },
  {
   "cell_type": "code",
   "execution_count": null,
   "metadata": {},
   "outputs": [],
   "source": []
  }
 ]
}